Workbook

Sheet Contents
A1: Chest X-ray Multi-Label Classification: Research Results
A2: Cascade results (sheets 4–5) and the distillation follow-up (sheet 7) use the official NIH ChestX-ray14 split, one training seed (42), no test-time augmentation. Updated 2026-09-25 (results_s42, results_distill).
A3: Two different test sets are in this workbook. Team models (sheet 3) were tested on a random patient split (15,917 images). The cascade models (sheets 4–5) were tested on the official NIH test list (25,596 images), which is harder. Never compare numbers across the two.
A5: Sheet | B5: What it contains
A6: 1. Dataset | B6: Dataset overview, disease counts and prevalence, split sizes, and how the official test set differs from train/validation.
A7: 2. Model Details | B7: Architecture and training setup for the 7 team models (random split) and the 2 cascade models (official split, seed 42).
A8: 3. Team Models (random split) | B8: Condensed benchmark of the 7 team models on their own random split: headline metrics, per-disease AUROC / F1 / precision / recall, key findings.
A9: 4. Official Split Results | B9: Final seed-42 results on the official test set: CNN, RAD-DINO, their average and the cascade, with 95% CIs, significance tests, per-disease results and training logs.
A10: 5. Two-Stage Cascade | B10: How the cascade works, the gate sweep, per-image vs per-finding routing, real compute cost (live formulas), which diseases the CNN decides, and the findings.
A11: 6. Two-Stage (Random Split) | B11: Restored 2026-09-25 at user request: the cascade experiment on its own random 70/15/15 split (16,724 test images), previously removed from this workbook. Kept separate from sheet 5 (official split) -- do not compare the two.
A12: 7. Distillation | B12: Follow-up to the cascade (added 2026-09-25): a ConvNeXt-Tiny trained on the soft predictions of the CNN + RAD-DINO average. Go/no-go check, training curve, test results with CIs, paired tests, outcome against the pre-registered rules, gap closed, per-finding AUROC, silent misses, and accuracy vs cost for all systems.
A13: Removed on 2026-09-24: the earlier cascade experiment on a random 70/15/15 split (test 16,724 images; old sheets 7–8 and its rows/columns elsewhere), and the 3-seed / TTA tables of the official split. The previous file is kept in _archive/.

Sheet 1. Dataset
A1: 1. Dataset
A2: NIH ChestX-ray14. Official split = official test list; validation = 15% of the train_val patients (seed 42); train = the rest. Source: T1_dataset_characteristics.csv (split_sha256 b9f2fbc9…).
A4: A. Dataset overview
A5: Dataset | B5: Modality | C5: Task | D5: # Diseases (labels) | E5: Total images | F5: Total patients | G5: Label source | I5: Notes
A6: NIH ChestX-ray14 | B6: Chest X-ray | C6: Multi-label classification | D6: 14 | E6: 112120 | F6: 30805 | G6: Text-mined from radiology reports (not verified against images, so labels are noisy) | I6: Several X-rays can come from one patient, so splits must be patient-level to avoid leakage.
A8: B. Split sizes
A9: Split | B9: Used by | C9: Train images | D9: Val images | E9: Test images | F9: Train patients | G9: Val patients | H9: Test patients | I9: Notes
A10: Official NIH split | B10: Cascade models (sheets 4–5) | C10: 73916 | D10: 12608 | E10: 25596 | F10: 23806 | G10: 4202 | H10: 2797 | I10: Test = official test_list.txt. Patient-level, no overlap.
A11: Random patient split | B11: Team models (sheet 3) | C11: 78596 | D11: 17591 | E11: 15917 | F11: n/r | G11: n/r | H11: n/r | I11: Split method not documented; 16 of 112,120 images unaccounted for.
A13: C. Official split: how the test set differs from train and validation
A14: Characteristic | B14: Train | C14: Validation | D14: Test | E14: Test ÷ validation | I14: Comment
A15: Images | B15: 73916 | C15: 12608 | D15: 25596
A16: Patients | B16: 23806 | C16: 4202 | D16: 2797
A17: Images per patient | B17: 3.1049315 | C17: 3.000476 | D17: 9.1512335 | E17: =D17/C17 -> 3.0499273 | I17: Test patients have many follow-up films (sicker, repeatedly imaged).
A18: Findings per image | B18: 0.62554795 | C18: 0.6132614 | D18: 1.0629004 | E18: =D18/C18 -> 1.7331931 | I18: Test images carry ~1.7x more findings.
A19: All-negative images | B19: 43075 | C19: 7425 | D19: 9861
A20: PA (standing) view share | B20: 0.64860111 | C20: 0.65609137 | D20: 0.43350524 | E20: =D20/C20 -> 0.66073912 | I20: More AP (bedside) films in test.
A21: Male share | B21: 0.5622328 | C21: 0.54727157 | D21: 0.58141897 | E21: =D21/C21 -> 1.0623957
A22: Median age | B22: 49 | C22: 49 | D22: 49 | E22: =D22/C22 -> 1
A23: Because of this shift, results tuned on validation (thresholds, the cascade gate) behave differently on test. It is the main reason the cascade saves little compute on the official test set (sheet 5).
A25: D. Diseases: positives and prevalence
A26: Disease | B26: Train prevalence | C26: Validation prevalence | D26: Official test positives | E26: Official test prevalence | F26: Test ÷ validation prevalence | G26: Team test-set positives (15,917 img) | H26: Team test-set prevalence | I26: Comment
A27: Infiltration | B27: 0.1603577 | C27: 0.15299809 | D27: 6112 | E27: 0.23878731 | F27: =E27/C27 -> 1.5607208 | G27: 2777 | H27: 0.1745
A28: Effusion | B28: 0.10031658 | C28: 0.09866751 | D28: 4658 | E28: 0.18198156 | F28: =E28/C28 -> 1.844392 | G28: 1755 | H28: 0.1103
A29: Atelectasis | B29: 0.094742678 | C29: 0.1012849 | D29: 3279 | E29: 0.12810595 | F29: =E29/C29 -> 1.264808 | G29: 1685 | H29: 0.1059
A30: Pneumothorax | B30: 0.030940527 | C30: 0.027760152 | D30: 2665 | E30: 0.10411783 | F30: =E30/C30 -> 3.7506219 | G30: 703 | H30: 0.0442 | I30: Largest jump: 3.7x more common in test.
A31: Consolidation | B31: 0.033578657 | C31: 0.029346447 | D31: 1815 | E31: 0.070909515 | F31: =E31/C31 -> 2.4162896 | G31: 563 | H31: 0.0354
A32: Mass | B32: 0.046701662 | C32: 0.046161167 | D32: 1748 | E32: 0.068291917 | F32: =E32/C32 -> 1.4794235 | G32: 848 | H32: 0.0533
A33: Nodule | B33: 0.054683696 | C33: 0.052823603 | D33: 1623 | E33: 0.063408345 | F33: =E33/C33 -> 1.200379 | G33: 894 | H33: 0.0562
A34: Pleural Thickening | B34: 0.025298988 | C34: 0.029505076 | D34: 1143 | E34: 0.044655416 | F34: =E34/C34 -> 1.5134825 | G34: 444 | H34: 0.0279
A35: Emphysema | B35: 0.017235782 | C35: 0.011817893 | D35: 1093 | E35: 0.042701986 | F35: =E35/C35 -> 3.6133332 | G35: 351 | H35: 0.0221
A36: Cardiomegaly | B36: 0.01965745 | C36: 0.02014594 | D36: 1069 | E36: 0.041764338 | F36: =E36/C36 -> 2.0730896 | G36: 367 | H36: 0.0231
A37: Edema | B37: 0.016248174 | C37: 0.014038705 | D37: 925 | E37: 0.03613846 | F37: =E37/C37 -> 2.5742018 | G37: 343 | H37: 0.0215
A38: Pneumonia | B38: 0.010038422 | C38: 0.010628172 | D38: 555 | E38: 0.021683076 | F38: =E38/C38 -> 2.040151 | G38: 210 | H38: 0.0132
A39: Fibrosis | B39: 0.014218843 | C39: 0.015862944 | D39: 435 | E39: 0.016994843 | F39: =E39/C39 -> 1.071355 | G39: 228 | H39: 0.0143
A40: Hernia | B40: 0.0015287624 | C40: 0.0022208123 | D40: 86 | E40: 0.0033599001 | F40: =E40/C40 -> 1.512915 | G40: 62 | H40: 0.0039
A41: Prevalence = share of images with the disease. The official test set has higher prevalence for every disease; Pneumothorax and Emphysema are 3–4x more common than in validation.

Sheet 2. Model Details
A1: 2. Model Details
A2: Columns B–H: team models (random split, sheet 3). Columns I–J: the two cascade models (official split, seed 42, sheets 4–5). The two groups were trained and tested on different splits.
A4: A. Architecture and training setup
A5: Attribute | B5: Hasib | C5: Marjia | D5: Tanzil | E5: BioViL-T | F5: ConvNeXt-Base | G5: ConvNeXt-Small | H5: RAD-DINO | I5: Cascade stage 1: ConvNeXt-Tiny (official split, seed 42) | J5: Cascade stage 2: RAD-DINO (official split, seed 42)
A6: Split / test set | B6: Random split, 15,917 test images | C6: Random split, 15,917 test images | D6: Random split, 15,917 test images | E6: Random split, 15,917 test images | F6: Random split, 15,917 test images | G6: Random split, 15,917 test images | H6: Random split, 15,917 test images | I6: Official NIH split, 25,596 test images | J6: Official NIH split, 25,596 test images
A7: Dataset | B7: NIH ChestX-ray14 | C7: NIH ChestX-ray14 | D7: NIH ChestX-ray14 | E7: NIH ChestX-ray14 | F7: NIH ChestX-ray14 | G7: NIH ChestX-ray14 | H7: NIH ChestX-ray14 | I7: NIH ChestX-ray14 (official split) | J7: NIH ChestX-ray14 (official split)
A8: Backbone | B8: DenseNet-121 | C8: ConvNeXt-Tiny | D8: DenseNet-121 (improved) | E8: BioViL-T (vision-language transformer) | F8: ConvNeXt-Base | G8: ConvNeXt-Small | H8: RAD-DINO (ViT-B, 12 blocks) | I8: ConvNeXt-Tiny (convnext_tiny.fb_in22k_ft_in1k) | J8: RAD-DINO (microsoft/rad-dino, ViT-B/14)
A9: Library | B9: torchxrayvision | C9: timm | D9: torchxrayvision | E9: Not stated in source | F9: timm | G9: timm 1.0.26 | H9: HuggingFace | I9: timm | J9: HuggingFace transformers
A10: Pre-training data | B10: Chest X-rays (NIH + other CXR sources) | C10: ImageNet-22k then ImageNet-1k | D10: Chest X-rays (NIH + CheXpert + MIMIC + PadChest + RSNA + OpenI) | E10: Vision-language pre-training on biomedical image + text data | F10: ImageNet-22k then ImageNet-1k | G10: ImageNet-22k then ImageNet-1k at 384px | H10: Self-supervised DINOv2 on chest X-rays | I10: ImageNet-22k then ImageNet-1k | J10: Self-supervised DINOv2 on chest X-rays
A11: Feature dimension | B11: 1024 | C11: 768 | D11: 1024 | E11: 512 | F11: 1792 | G11: 768 (1536 after dual pooling) | H11: 768 (1536 after dual pooling) | I11: 768 | J11: 1536 (CLS + mean of patch tokens)
A12: Input channels | B12: 1 (grayscale) | C12: 3 (RGB) | D12: 1 (grayscale) | E12: Not stated in source | F12: Not stated in source | G12: 3 (RGB) | H12: 3 (RGB) | I12: 3 (grayscale replicated) | J12: 3 (grayscale replicated)
A13: Input size | B13: Not stated in source | C13: Not stated in source | D13: Not stated in source | E13: 448 x 448 | F13: 380 x 380 | G13: 384 x 384 | H13: 518 x 518 | I13: 384 x 384 | J13: 518 x 518
A14: Preprocessing | B14: xrv normalization | C14: ImageNet normalization | D14: xrv custom normalization | E14: Not stated in source | F14: Not stated in source | G14: ImageNet normalization | H14: RAD-DINO normalization (mean 0.5307, std 0.2583) | I14: ImageNet normalization | J14: RAD-DINO normalization (mean 0.5307, std 0.2583)
A15: Classification head | B15: Custom 14-way | C15: Custom 14-way | D15: Custom 14-way | E15: Custom 14-way | F15: Custom 14-way | G15: Custom 14-way | H15: Custom 14-way | I15: Dropout (0.2) + linear → 14 logits | J15: Linear → 14 logits
A16: Loss function | B16: BCEWithLogitsLoss | C16: BCEWithLogitsLoss | D16: Class-weighted BCEWithLogitsLoss | E16: Not stated in source | F16: Not stated in source | G16: AsymmetricLoss (g_neg=4, g_pos=1, clip=0.05) | H16: AsymmetricLoss (g_neg=4, g_pos=1, clip=0.05) | I16: AsymmetricLoss (g_neg=4, g_pos=1, clip=0.05) | J16: AsymmetricLoss (g_neg=4, g_pos=1, clip=0.05)
A17: Training scheme | B17: Single-phase | C17: Single-phase | D17: Two-phase (warmup then fine-tune) | E17: Two-phase (warmup then fine-tune) | F17: Two-phase (warmup then fine-tune) | G17: Two-phase (2 warmup, then last 2 of 4 stages) | H17: Two-phase (3 warmup, then last 8 of 12 ViT blocks) | I17: 1 warmup epoch (head only, LR 1e-3), then full fine-tuning (head 1e-4, backbone 1e-4), up to 8 epochs | J17: 2 warmup epochs (head only, LR 1e-3), then last 8 of 12 blocks with layer-wise LR decay 0.8 (backbone 2e-5, head 2e-4), up to 4 epochs, EMA 0.999
A18: Optimizer / regularization | B18: Not stated in source | C18: Not stated in source | D18: Not stated in source | E18: Not stated in source | F18: Not stated in source | G18: Not stated in source | H18: Not stated in source | I18: AdamW, weight decay 0.05, cosine schedule, drop-path 0.1, grad clip 1.0, fp16, early stop on val macro AUROC (patience 2) | J18: Same as ConvNeXt-Tiny, plus EMA of weights (0.999)
A19: Augmentation | B19: Not stated in source | C19: Not stated in source | D19: Not stated in source | E19: Not stated in source | F19: Not stated in source | G19: Not stated in source | H19: Not stated in source | I19: Random resized crop (0.85–1.0), horizontal flip, ±7° rotation (p 0.5), brightness/contrast ±0.1. No TTA. | J19: Same as ConvNeXt-Tiny. No TTA.
A20: Calibration | B20: Temperature scaling | C20: Temperature scaling | D20: Temperature scaling | E20: Temperature scaling | F20: Temperature scaling | G20: Temperature scaling | H20: Temperature scaling | I20: Per-class Platt scaling | J20: Per-class Platt scaling
A21: Calibrated temperature | B21: n/r | C21: n/r | D21: 0.6821 | E21: 0.6971 | F21: 1.9554 | G21: 1.2052 | H21: 1.1278 | I21: n/a (per-class Platt) | J21: n/a (per-class Platt)
A22: Thresholding | B22: Fixed at 0.50 | C22: Tuned per class | D22: Tuned per class | E22: Tuned per class (0.50 report also given) | F22: Tuned per class (0.50 report also given) | G22: Five strategies compared | H22: Five strategies compared | I22: Per-class, tuned on validation to maximise F1 | J22: Per-class, tuned on validation to maximise F1
A23: Total parameters | B23: n/r | C23: n/r | D23: n/r | E23: n/r | F23: n/r | G23: 49479279 | H23: 86605071 | I23: 27830894 | J23: 86601998
A24: Trainable parameters | B24: n/r | C24: n/r | D24: n/r | E24: 27357111 | F24: 17573719 | G24: 48244239 | H24: 56741391 | I24: 27830894 | J24: 56738318
A25: Batch size | B25: n/r | C25: n/r | D25: n/r | E25: 12 | F25: 16 | G25: 16 | H25: 12 | I25: 32 | J25: 12
A26: Warmup epochs | B26: n/r | C26: n/r | D26: n/r | E26: 4 | F26: 4 | G26: 2 | H26: 3 | I26: 1 | J26: 2
A27: Fine-tune epochs | B27: n/r | C27: n/r | D27: n/r | E27: 6 | F27: 6 | G27: 3 (early stop) | H27: 3 (early stop) | I27: 8 epochs run (1 warm-up + 7 fine-tune, early stop); best = epoch 6 | J27: 6 epochs run (2 warm-up + 4 fine-tune); best = epoch 4
A28: Best validation macro AUROC | B28: n/r | C28: n/r | D28: n/r | E28: 0.8274 | F28: 0.8082 | G28: 0.7982 | H28: 0.8483 | I28: 0.85977526 | J28: 0.86511315
A29: Test macro AUROC | B29: 0.76 | C29: 0.831 | D29: 0.813 | E29: 0.836 | F29: 0.819 | G29: 0.8061 | H29: 0.8513 | I29: 0.82630389 | J29: 0.83638611
A30: Total training time | B30: n/r | C30: n/r | D30: n/r | E30: n/r | F30: n/r | G30: 7,655 s (~2.1 h) | H30: 26,749 s (~7.4 h) + 940 s to collect logits | I30: 2.77 h | J30: 6.56 h
A31: Inference time (ms/image, T4, batch 32) | B31: n/r | C31: n/r | D31: n/r | E31: n/r | F31: n/r | G31: n/r | H31: n/r | I31: 4.0095115 | J31: 22.849385
A32: Test set size (images) | B32: 15917 | C32: 15917 | D32: 15917 | E32: 15917 | F32: 15917 | G32: 15917 | H32: 15917 | I32: 25596 | J32: 25596
A33: Source notebook | B33: https://www.kaggle.com/code/hasibulhossain293/xrvlm-densenet-xrv-fulldata | C33: https://www.kaggle.com/code/marjiaislam/convnext-tiny | D33: https://www.kaggle.com/code/ashrafulislamtanzil/data-mining/edit/run/340283180 | E33: https://www.kaggle.com/code/marjiaislam/biovil-t | F33: https://www.kaggle.com/code/ashrafulislamtanzil/test2 | G33: https://www.kaggle.com/code/marjiaislam/convnext-small | H33: https://www.kaggle.com/code/marjiaislam/rad-dino-v2 | I33: https://www.kaggle.com/code/hasibulhossain293/notebooka74861b945 | J33: https://www.kaggle.com/code/hasibulhossain293/notebooka74861b945
A35: Tanzil's DenseNet-121 link is a private '/edit/run/...' editor URL, so it only opens for people with edit access. ConvNeXt-Base reports only 17.6M trainable parameters, far below a full ConvNeXt-Base, so part of the backbone was likely frozen. The cascade stages are described in sheet 5. Green-header columns K and L are the official NIH split runs (mean of seeds 42, 43, 44; inference time measured at batch 32 on a T4, fp16). Their numbers are not comparable with the other columns, which use different random splits. Cascade timing: forward pass only, fp16, Tesla T4, median of 3 repeats (timing_*.json, Kaggle session T, 2026-09-24). At batch 1: ConvNeXt-Tiny 11.4 ms, RAD-DINO 22.2 ms.

Sheet 3. Team Models (random split)
A1: 3. Team Models — random split benchmark (condensed)
A2: Seven team models plus a logit-average ensemble, all tested on the same random-split test set (15,917 images). Values as reported in each model's notebook/log (not recomputed from predictions). n/r = not reported.
A3: Different split from sheets 4–5. These numbers must not be compared with the official-split results: the official test set is harder (e.g. RAD-DINO: 0.851 here vs 0.836 on the official test).
A5: A. Headline benchmark
A6: Model | B6: Type | C6: Pre-training | D6: Macro AUROC | E6: Macro F1 | F6: Micro F1 | G6: Weighted F1 | H6: Macro AUPRC | I6: Macro precision | J6: Macro recall | K6: Macro specificity | L6: Macro MCC | M6: Hamming accuracy | N6: Subset accuracy | O6: Rank (AUROC) | P6: Thresholds
A7: Hasib (DenseNet-121) | B7: CNN | C7: Chest X-rays | D7: 0.76 | E7: 0.18 | F7: 0.2 | G7: 0.27 | H7: n/r | I7: 0.12 | J7: 0.56 | K7: n/r | L7: n/r | M7: n/a | N7: n/a | O7: 8 | P7: Fixed 0.50
A8: Marjia (ConvNeXt-Tiny) | B8: CNN | C8: ImageNet | D8: 0.831 | E8: 0.3 | F8: 0.36 | G8: 0.37 | H8: n/r | I8: 0.27 | J8: 0.37 | K8: n/r | L8: n/r | M8: 0.921 | N8: 0.429 | O8: 4 | P8: Tuned per class
A9: Tanzil (DenseNet-121 improved) | B9: CNN | C9: Chest X-rays | D9: 0.813 | E9: 0.28 | F9: 0.33 | G9: 0.35 | H9: n/r | I9: 0.23 | J9: 0.39 | K9: n/r | L9: n/r | M9: 0.906 | N9: 0.395 | O9: 6 | P9: Tuned per class
A10: BioViL-T | B10: Vision-language | C10: Biomedical image + text | D10: 0.836 | E10: 0.32 | F10: 0.37 | G10: 0.39 | H10: n/r | I10: 0.29 | J10: 0.4 | K10: n/r | L10: n/r | M10: 0.92 | N10: 0.415 | O10: 3 | P10: Tuned per class
A11: ConvNeXt-Base | B11: CNN | C11: ImageNet | D11: 0.819 | E11: 0.29 | F11: 0.36 | G11: 0.36 | H11: n/r | I11: 0.25 | J11: 0.36 | K11: n/r | L11: n/r | M11: 0.917 | N11: 0.394 | O11: 5 | P11: Tuned per class
A12: ConvNeXt-Small | B12: CNN | C12: ImageNet | D12: 0.806 | E12: 0.31 | F12: n/r | G12: n/r | H12: 0.247 | I12: 0.275 | J12: 0.381 | K12: 0.937 | L12: 0.273 | M12: n/r | N12: n/r | O12: 7 | P12: Best (F1) strategy
A13: RAD-DINO | B13: ViT (self-supervised) | C13: Chest X-rays (DINOv2) | D13: 0.851 | E13: 0.36 | F13: n/r | G13: n/r | H13: 0.295 | I13: 0.311 | J13: 0.451 | K13: 0.938 | L13: 0.328 | M13: n/r | N13: n/r | O13: 1 | P13: Best (F1) strategy
A14: Ensemble: logit average of first five | B14: Ensemble | C14: – | D14: 0.849 | E14: n/r | F14: n/r | G14: n/r | H14: n/r | I14: n/r | J14: n/r | K14: n/r | L14: n/r | M14: n/r | N14: n/r | O14: 2 | P14: n/r
A15: Team models, all on the same 15,917-image test set. F1 for Marjia, Tanzil, BioViL-T and ConvNeXt-Base uses tuned thresholds (like-for-like). Hasib uses a fixed 0.50. ConvNeXt-Small and RAD-DINO use their best (F1) strategy. Hamming accuracy is inflated because most labels are negative: predicting 'no disease' everywhere already scores ~0.90.
A17: B. Per-disease AUROC (green = best model for that disease)
A18: Disease | B18: Test cases | C18: Hasib (DenseNet-121) | D18: Marjia (ConvNeXt-Tiny) | E18: Tanzil (DenseNet-121 improved) | F18: BioViL-T | G18: ConvNeXt-Base | H18: ConvNeXt-Small | I18: RAD-DINO | J18: Best model
A19: Hernia | B19: 62 | C19: 0.788 | D19: 0.905 | E19: 0.938 | F19: 0.916 | G19: 0.852 | H19: 0.906 | I19: 0.967 | J19: RAD-DINO
A20: Emphysema | B20: 351 | C20: 0.7 | D20: 0.902 | E20: 0.78 | F20: 0.889 | G20: 0.909 | H20: 0.923 | I20: 0.947 | J20: RAD-DINO
A21: Edema | B21: 343 | C21: 0.849 | D21: 0.914 | E21: 0.887 | F21: 0.909 | G21: 0.904 | H21: 0.896 | I21: 0.91 | J21: Marjia (ConvNeXt-Tiny)
A22: Pneumothorax | B22: 703 | C22: 0.766 | D22: 0.88 | E22: 0.821 | F22: 0.873 | G22: 0.881 | H22: 0.872 | I22: 0.91 | J22: RAD-DINO
A23: Cardiomegaly | B23: 367 | C23: 0.885 | D23: 0.905 | E23: 0.908 | F23: 0.904 | G23: 0.883 | H23: 0.885 | I23: 0.901 | J23: Tanzil (DenseNet-121 improved)
A24: Mass | B24: 848 | C24: 0.795 | D24: 0.853 | E24: 0.854 | F24: 0.875 | G24: 0.842 | H24: 0.827 | I24: 0.895 | J24: RAD-DINO
A25: Effusion | B25: 1755 | C25: 0.835 | D25: 0.876 | E25: 0.868 | F25: 0.882 | G25: 0.867 | H25: 0.869 | I25: 0.885 | J25: RAD-DINO
A26: Atelectasis | B26: 1685 | C26: 0.755 | D26: 0.806 | E26: 0.791 | F26: 0.823 | G26: 0.801 | H26: 0.791 | I26: 0.839 | J26: RAD-DINO
A27: Fibrosis | B27: 228 | C27: 0.735 | D27: 0.799 | E27: 0.797 | F27: 0.798 | G27: 0.806 | H27: 0.789 | I27: 0.833 | J27: RAD-DINO
A28: Nodule | B28: 894 | C28: 0.652 | D28: 0.754 | E28: 0.734 | F28: 0.787 | G28: 0.749 | H28: 0.696 | I28: 0.813 | J28: RAD-DINO
A29: Consolidation | B29: 563 | C29: 0.779 | D29: 0.783 | E29: 0.794 | F29: 0.799 | G29: 0.791 | H29: 0.767 | I29: 0.797 | J29: BioViL-T
A30: Pleural Thickening | B30: 444 | C30: 0.726 | D30: 0.772 | E30: 0.746 | F30: 0.771 | G30: 0.749 | H30: 0.708 | I30: 0.79 | J30: RAD-DINO
... A32: Infiltration | B32: 2777 | C32: 0.664 | D32: 0.708 | E32: 0.695 | F32: 0.706 | G32: 0.702 | H32: 0.688 | I32: 0.702 | J32: Marjia (ConvNeXt-Tiny)
A33: Red rows = hardest diseases. RAD-DINO leads on 12 of the 14 diseases and reaches 0.851, above the logit-average ensemble of the first five models (0.849). Within the ConvNeXt family, bigger/higher resolution did not help: Tiny 0.831 > Base 0.819 > Small-384 0.806.
A35: C. Per-disease F1
A36: Disease | B36: Test cases | C36: Hasib (DenseNet-121) | D36: Marjia (ConvNeXt-Tiny) | E36: Tanzil (DenseNet-121 improved) | F36: BioViL-T | G36: ConvNeXt-Base | H36: ConvNeXt-Small | I36: RAD-DINO | J36: Best model
A37: Infiltration | B37: 2777 | C37: 0.34 | D37: 0.4 | E37: 0.39 | F37: 0.4 | G37: 0.4 | H37: 0.39 | I37: 0.39 | J37: Marjia (ConvNeXt-Tiny), BioViL-T, ConvNeXt-Base
A38: Effusion | B38: 1755 | C38: 0.42 | D38: 0.52 | E38: 0.5 | F38: 0.54 | G38: 0.5 | H38: 0.47 | I38: 0.49 | J38: BioViL-T
A39: Atelectasis | B39: 1685 | C39: 0.33 | D39: 0.4 | E39: 0.38 | F39: 0.42 | G39: 0.39 | H39: 0.37 | I39: 0.43 | J39: RAD-DINO
A40: Nodule | B40: 894 | C40: 0.16 | D40: 0.29 | E40: 0.26 | F40: 0.34 | G40: 0.29 | H40: 0.24 | I40: 0.35 | J40: RAD-DINO
A41: Mass | B41: 848 | C41: 0.28 | D41: 0.41 | E41: 0.41 | F41: 0.44 | G41: 0.4 | H41: 0.42 | I41: 0.44 | J41: BioViL-T, RAD-DINO
A42: Pneumothorax | B42: 703 | C42: 0.18 | D42: 0.39 | E42: 0.29 | F42: 0.4 | G42: 0.39 | H42: 0.41 | I42: 0.46 | J42: RAD-DINO
A43: Consolidation | B43: 563 | C43: 0.16 | D43: 0.19 | E43: 0.19 | F43: 0.21 | G43: 0.18 | H43: 0.02 | I43: 0.01 | J43: BioViL-T
A44: Pleural Thickening | B44: 444 | C44: 0.11 | D44: 0.16 | E44: 0.17 | F44: 0.19 | G44: 0.16 | H44: 0.05 | I44: 0.16 | J44: BioViL-T
...

Sheet 4. Official Split Results
A1: 4. Official NIH Split — Final Results (seed 42)
A2: Test = official NIH test list (25,596 images, 2,797 patients). One training seed (42), no TTA. Per-class Platt calibration and per-class F1-max thresholds fitted on validation only. 95% CI = patient-level bootstrap, 1,000 resamples. Source: results_s42 (T2, T3, T5).
A4: A. Main results (test set)
A5: System | B5: Macro AUROC | C5: 95% CI | D5: Macro AUPRC | E5: 95% CI | F5: Macro F1 | G5: 95% CI | H5: Micro F1 | I5: 95% CI | J5: Macro precision | K5: Macro recall | L5: Macro specificity | M5: ECE (lower = better)
A6: CNN alone (ConvNeXt-Tiny) | B6: 0.82630389 | C6: 0.820–0.832 | D6: 0.29884675 | E6: 0.285–0.315 | F6: 0.35391016 | G6: 0.334–0.369 | H6: 0.41717 | I6: 0.409–0.425 | J6: 0.31884096 | K6: 0.43042032 | L6: 0.90396065 | M6: 0.011726549
A7: RAD-DINO alone | B7: 0.83638611 | C7: 0.830–0.842 | D7: 0.32232227 | E7: 0.310–0.337 | F7: 0.37877978 | G7: 0.365–0.390 | H7: 0.43170705 | I7: 0.424–0.439 | J7: 0.33618678 | K7: 0.46156028 | L7: 0.90217277 | M7: 0.01061048
A8: Average of both (every image) | B8: 0.84277771 | C8: 0.837–0.848 | D8: 0.32918472 | E8: 0.316–0.343 | F8: 0.38178977 | G8: 0.367–0.393 | H8: 0.44211246 | I8: 0.434–0.449 | J8: 0.34114871 | K8: 0.45610688 | L8: 0.90919431 | M8: 0.010326673
A9: Cascade t = 0.80 (selected on val) | B9: 0.83247514 | C9: 0.826–0.838 | D9: 0.31761424 | E9: 0.305–0.332 | F9: 0.37088237 | G9: 0.356–0.382 | H9: 0.42734521 | I9: 0.419–0.435 | J9: 0.34010485 | K9: 0.44541387 | L9: 0.90361631 | M9: 0.011292517
A10: Green = best in the column. Highlighted row = the cascade selected on validation (sheet 5). The average of both models is best on AUROC, AUPRC and F1 but runs both models on every image.
A12: B. Is the difference real? (paired patient-level bootstrap, Holm-corrected)
A13: Comparison (A − B) | B13: Metric | C13: Difference | D13: 95% CI | E13: Relative % | F13: Holm p | G13: Significant?
A14: RAD-DINO alone − CNN alone | B14: Macro AUROC | C14: 0.010082216 | D14: +0.0063 to +0.0140 | E14: 0.012201583 | F14: 0.005994006 | G14: Yes
A15: Average of both − CNN alone | B15: Macro AUROC | C15: 0.016473815 | D15: +0.0139 to +0.0193 | E15: 0.019936751 | F15: 0.005994006 | G15: Yes
A16: Cascade t = 0.80 − CNN alone | B16: Macro AUROC | C16: 0.0061712486 | D16: +0.0034 to +0.0089 | E16: 0.0074684975 | F16: 0.005994006 | G16: Yes
A17: Average of both − RAD-DINO alone | B17: Macro AUROC | C17: 0.0063915989 | D17: +0.0049 to +0.0079 | E17: 0.0076419237 | F17: 0.005994006 | G17: Yes
A18: Cascade t = 0.80 − RAD-DINO alone | B18: Macro AUROC | C18: -0.0039109672 | D18: -0.0065 to -0.0017 | E18: -0.0046760307 | F18: 0.005994006 | G18: Yes
A19: Cascade t = 0.80 − Average of both | B19: Macro AUROC | C19: -0.010302566 | D19: -0.0129 to -0.0084 | E19: -0.012224535 | F19: 0.005994006 | G19: Yes
A20: RAD-DINO alone − CNN alone | B20: Macro AUPRC | C20: 0.023475521 | D20: +0.0131 to +0.0339 | E20: 0.07855371 | F20: 0.005994006 | G20: Yes
A21: Average of both − CNN alone | B21: Macro AUPRC | C21: 0.030337969 | D21: +0.0229 to +0.0379 | E21: 0.10151681 | F21: 0.005994006 | G21: Yes
A22: Cascade t = 0.80 − CNN alone | B22: Macro AUPRC | C22: 0.01876749 | D22: +0.0099 to +0.0290 | E22: 0.062799713 | F22: 0.005994006 | G22: Yes
A23: Average of both − RAD-DINO alone | B23: Macro AUPRC | C23: 0.0068624481 | D23: +0.0028 to +0.0113 | E23: 0.021290642 | F23: 0.005994006 | G23: Yes
A24: Cascade t = 0.80 − RAD-DINO alone | B24: Macro AUPRC | C24: -0.0047080307 | D24: -0.0085 to -0.0012 | E24: -0.014606594 | F24: 0.01 | G24: Yes
A25: Cascade t = 0.80 − Average of both | B25: Macro AUPRC | C25: -0.011570479 | D25: -0.0151 to -0.0077 | E25: -0.035148894 | F25: 0.005994006 | G25: Yes
... A37: Cascade t = 0.80 − Average of both | B37: Micro F1 | C37: -0.014767245 | D37: -0.0182 to -0.0113 | E37: -0.033401558 | F37: 0.005994006 | G37: Yes
A38: Significant = CI excludes 0 and Holm p < 0.05. With 25,596 paired images even small gaps are significant: the cascade is 0.004 AUROC and 0.008 macro F1 below RAD-DINO alone. Yellow = not significant (average vs RAD-DINO on macro F1).
A40: C. Validation vs test (macro values) — every system drops on the official test set
A41: System | B41: Val AUROC | C41: Test AUROC | D41: Change | E41: Val F1 | F41: Test F1 | G41: Change
A42: CNN alone (ConvNeXt-Tiny) | B42: 0.85977526 | C42: 0.82630389 | D42: =C42-B42 -> -0.033471361 | E42: 0.35051272 | F42: 0.35391016 | G42: =F42-E42 -> 0.0033974428
A43: RAD-DINO alone | B43: 0.86511315 | C43: 0.83638611 | D43: =C43-B43 -> -0.028727035 | E43: 0.37218226 | F43: 0.37877978 | G43: =F43-E43 -> 0.0065975115
A44: Average of both (every image) | B44: 0.87350997 | C44: 0.84277771 | D44: =C44-B44 -> -0.030732256 | E44: 0.37273628 | F44: 0.38178977 | G44: =F44-E44 -> 0.0090534969
A45: Cascade t = 0.80 (selected on val) | B45: 0.8637643 | C45: 0.83247514 | D45: =C45-B45 -> -0.031289153 | E45: 0.36629462 | F45: 0.37088237 | G45: =F45-E45 -> 0.0045877492
A46: AUROC falls by about 0.03 for every system: this is the harder official test set (sheet 1, section C), not a cascade problem. F1 rises slightly because the test set has higher prevalence, which makes F1 easier.
A48: D. Per-disease AUROC (test)
A49: Disease | B49: Test cases | C49: Prevalence | D49: CNN alone | E49: RAD-DINO alone | F49: Average of both | G49: Cascade
A50: Infiltration | B50: 6112 | C50: 0.23878731 | D50: 0.70898552 | E50: 0.70942717 | F50: 0.71684055 | G50: 0.70750891
A51: Effusion | B51: 4658 | C51: 0.18198156 | D51: 0.83933057 | E51: 0.84250478 | F51: 0.84776989 | G51: 0.84164504
A52: Atelectasis | B52: 3279 | C52: 0.12810595 | D52: 0.79046467 | E52: 0.79802443 | F52: 0.80433389 | G52: 0.79487516
A53: Pneumothorax | B53: 2665 | C53: 0.10411783 | D53: 0.88229402 | E53: 0.90407989 | F53: 0.90530959 | G53: 0.90173011
A54: Consolidation | B54: 1815 | C54: 0.070909517 | D54: 0.7606011 | E54: 0.76083792 | F54: 0.77198758 | G54: 0.76003229
A55: Mass | B55: 1748 | C55: 0.068291921 | D55: 0.84584396 | E55: 0.85129688 | F55: 0.85983639 | G55: 0.84798217
...

Sheet 5. Two-Stage Cascade
A1: 5. Two-Stage Cascade: CNN (ConvNeXt-Tiny) → Transformer (RAD-DINO) — official split, seed 42
A2: A fast CNN decides the images it is confident about; RAD-DINO is called only for the rest. Everything is chosen on validation and then applied unchanged to the official test set. Source: results_s42 (T4, T5, T6, timing_*.json).
A4: A. How it works
A5: Component | B5: Details
A6: Stage 1 (CNN) | B6: ConvNeXt-Tiny, 384 px, scores all 14 findings.
A7: Calibration | B7: Per-class Platt scaling, fitted on validation, so scores behave like probabilities.
A8: Gate | B8: A finding is 'confident' if p ≤ 1 − t (No) or p ≥ t (Yes). An image stays with the CNN only if ALL 14 findings are confident.
A9: Stage 2 (Transformer) | B9: RAD-DINO, 518 px, decides all 14 findings of every routed image (per-image routing).
A10: Decision thresholds | B10: Per class, re-tuned on validation to maximise F1 given the CNN's fixed decisions.
A11: Selection rule | B11: Cheapest gate (fewest validation images sent to RAD-DINO) whose validation macro F1 is within 0.01 of RAD-DINO alone.
A12: Selected | B12: Stage 2 = RAD-DINO, per-image routing, gate t=0.80 (flat).
A13: Seed / TTA | B13: One training seed (42); no test-time augmentation.
A15: B. Gate sweep (per-image routing)
A16: Stage 2 | B16: Gate | C16: Share to RAD-DINO (val) | D16: Share to RAD-DINO (test) | E16: Compute vs RAD-DINO (val) | F16: Compute vs RAD-DINO (test) | G16: Macro F1 (val) | H16: Macro F1 (test) | I16: Macro AUROC (test) | J16: Macro recall (test) | K16: Positive labels missed by CNN (test) | L16: Selected
A17: RAD-DINO | B17: flat t=0.70 | C17: 0.27308058 | D17: 0.56915143 | E17: 0.44855627 | F17: 0.74462711 | G17: 0.33902555 | H17: 0.34715893 | I17: 0.830321 | J17: 0.39490706 | K17: 7024
A18: RAD-DINO | B18: flat t=0.80 | C18: 0.44479695 | D18: 0.77566807 | E18: 0.62027264 | F18: 0.95114376 | G18: 0.36629462 | H18: 0.37088237 | I18: 0.83247514 | J18: 0.44541387 | K18: 2593 | L18: Yes
A19: RAD-DINO | B19: flat t=0.90 | C19: 0.73136104 | D19: 0.93276293 | E19: 0.90683672 | F19: 1.1082386 | G19: 0.36878141 | H19: 0.37939722 | I19: 0.83544409 | J19: 0.46404508 | K19: 466
A20: RAD-DINO | B20: flat t=0.95 | C20: 0.90696383 | D20: 0.98273168 | E20: 1.0824395 | F20: 1.1582074 | G20: 0.37190489 | H20: 0.37945004 | I20: 0.83632296 | J20: 0.4644687 | K20: 77
A21: RAD-DINO | B21: flat t=0.98 | C21: 0.99111675 | D21: 0.99859353 | E21: 1.1665924 | F21: 1.1740692 | G21: 0.37218226 | H21: 0.37879968 | I21: 0.83640203 | J21: 0.46156028 | K21: 1
A22: RAD-DINO | B22: per-class miss<=1% | C22: 0.99563769 | D22: 0.99886701 | E22: 1.1711134 | F22: 1.1743427 | G22: 0.37218226 | H22: 0.37877978 | I22: 0.83639338 | J22: 0.46156028 | K22: 1
A23: RAD-DINO | B23: per-class miss<=2% | C23: 0.98937183 | D23: 0.99781216 | E23: 1.1648475 | F23: 1.1732878 | G23: 0.37218226 | H23: 0.37877978 | I23: 0.83640416 | J23: 0.46156028 | K23: 3
A24: RAD-DINO | B24: per-class miss<=5% | C24: 0.96732234 | D24: 0.99124863 | E24: 1.142798 | F24: 1.1667243 | G24: 0.37215113 | H24: 0.37876079 | I24: 0.83633144 | J24: 0.46151627 | K24: 17
A25: RAD-DINO | B25: per-class miss<=10% | C25: 0.91243655 | D25: 0.97937178 | E25: 1.0879122 | F25: 1.1548475 | G25: 0.37231304 | H25: 0.37877314 | I25: 0.83614311 | J25: 0.46144933 | K25: 65
A26: average | B26: flat t=0.70 | C26: 0.27308058 | D26: 0.56915143 | E26: 0.44855627 | F26: 0.74462711 | G26: 0.3402867 | H26: 0.35186214 | I26: 0.83385749 | J26: 0.37899135 | K26: 7024
A27: average | B27: flat t=0.80 | C27: 0.44479695 | D27: 0.77566807 | E27: 0.62027264 | F27: 0.95114376 | G27: 0.36515508 | H27: 0.37519355 | I27: 0.83719481 | J27: 0.43092719 | K27: 2593
A28: average | B28: flat t=0.90 | C28: 0.73136104 | D28: 0.93276293 | E28: 0.90683672 | F28: 1.1082386 | G28: 0.36924677 | H28: 0.38195904 | I28: 0.84142129 | J28: 0.45146351 | K28: 466
A29: average | B29: flat t=0.95 | C29: 0.90696383 | D29: 0.98273168 | E29: 1.0824395 | F29: 1.1582074 | G29: 0.37246385 | H29: 0.38324396 | I29: 0.84247237 | J29: 0.46935523 | K29: 77
A30: average | B30: flat t=0.98 | C30: 0.99111675 | D30: 0.99859353 | E30: 1.1665924 | F30: 1.1740692 | G30: 0.37273628 | H30: 0.38178977 | I30: 0.84278486 | J30: 0.45610688 | K30: 1
A31: Reference, RAD-DINO alone: macro F1 val 0.3722, test 0.3788; macro AUROC test 0.8364. Compute > 1.00 means the cascade costs MORE than running RAD-DINO on every image. Per-class gates (miss ≤ x%) are safe but send ~98–100% of images to RAD-DINO.
A33: C. Why the gate did not transfer: validation vs test for the selected gate (t = 0.80)
B34: Validation | C34: Test | D34: Test ÷ validation | E34: Comment
A35: Share sent to RAD-DINO | B35: 0.44479695 | C35: 0.77566807 | D35: =C35/B35 -> 1.74387 | E35: The CNN is unsure about far more test images.
A36: Compute vs RAD-DINO (batch 32) | B36: 0.62027264 | C36: 0.95114376 | D36: =C36/B36 -> 1.5334285 | E36: 38% saving on validation shrinks to 5% on test.
A37: Positive labels missed by the CNN | B37: 1977 | C37: 2593 | D37: =C37/B37 -> 1.3115832 | E37: Positives on CNN-decided images that the CNN called No.
A38: Findings per image | B38: 0.6132614 | C38: 1.0629004 | D38: =C38/B38 -> 1.7331931 | E38: Sicker test patients (sheet 1, C).
A39: Images per patient | B39: 3.000476 | C39: 9.1512335 | D39: =C39/B39 -> 3.0499273 | E39: Many follow-up films in test.
A40: About 60% of the jump in routing is explained by the measurable case mix (more findings per image, more images per patient). The rest: even test images labelled 'no finding' are routed more often, likely because of more bedside (AP) films, tubes and lines, and noisy labels.
A42: D. Compute: what the cascade actually costs (edit the blue inputs; the rest recalculates)
A43: Model | B43: ms/image, batch 1 | C43: ms/image, batch 32 | D43: Source
A44: ConvNeXt-Tiny (stage 1) | B44: 11.37152 | C44: 4.0095115 | D44: Measured: forward pass, fp16, Tesla T4, median of 3 repeats (Kaggle session T, 2026-09-24)
...

Sheet 6. Two-Stage (Random Split)
A1: Two-Stage Cascade — Random Split Experiment (restored, kept separate from sheet 5)
A2: Re-added at the user's request on 2026-09-25. This cascade (ConvNeXt-Tiny -> RAD-DINO, calibrated confidence gate) was evaluated on its own freshly-generated random 70/15/15 split (16,724 test images) -- NOT the official NIH split used in sheet 5 (25,596 test images) and NOT the random split used in sheet 3 (15,917 test images). This sheet was previously removed from this workbook on 2026-09-24 (see Contents, row 12) because the official-split cascade (sheet 5) superseded it as the reported result; it is restored here as a separate, clearly-labelled section. Do not compare these numbers with sheets 3-5.
A4: Dataset & Split (this experiment only)
A5: Split | B5: Images | C5: Patients
A6: Train | B6: 78299 | C6: 21563
A7: Validation | B7: 17097 | C7: 4621
A8: Test | B8: 16724 | C8: 4621
A9: Total | B9: 112120 | C9: 30805
A10: Random patient-level split (~70/15/15); no patient appears in more than one split. This split is different in size from the 15,917-image test set used on sheets 1–9, so it is a different dataset partition, not a rerun on the same held-out images.
A12: Main Comparison — Test Set, 16,724 Images (this experiment's own numbers)
A13: System | B13: → Stage 2 | C13: ms/image | D13: Macro AUROC | E13: Macro AUPRC | F13: Precision | G13: Recall | H13: Specificity | I13: Macro F1 | J13: Micro F1
A14: CNN alone (ConvNeXt-Tiny) | B14: 0% | C14: 4.5 | D14: 0.8577 | E14: 0.2921 | F14: 0.323 | G14: 0.4305 | H14: 0.9412 | I14: 0.3535 | J14: 0.4001
A15: RAD-DINO alone | B15: 100% | C15: 27.3 | D15: 0.8622 | E15: 0.2948 | F15: 0.3191 | G15: 0.4136 | H15: 0.9435 | I15: 0.3504 | J15: 0.4051
A16: Average of both | B16: 100% | C16: 31.8 | D16: 0.8698 | E16: 0.3095 | F16: 0.3257 | G16: 0.4321 | H16: 0.9468 | I16: 0.36 | J16: 0.4134
A17: Cascade t=0.80 (selected) | B17: 53.4% | C17: 19.1 | D17: 0.8654 | E17: 0.3072 | F17: 0.3328 | G17: 0.4316 | H17: 0.9482 | I17: 0.3721 | J17: 0.4128
A18: Cascade t=0.90 | B18: 80.1% | C18: 26.4 | D18: 0.8682 | E18: 0.3092 | F18: 0.3295 | G18: 0.425 | H18: 0.9481 | I18: 0.3601 | J18: 0.4134
A19: Selected configuration: per-image routing, Stage 2 = average of CNN and RAD-DINO logits (free once the CNN has run). Chosen automatically as the setting sending the fewest images to Stage 2 while keeping validation macro F1 within 0.01 of RAD-DINO alone.
A21: Statistical Significance (300 patient-level bootstrap resamples, 95% CI)
A22: Comparison | B22: Difference | C22: 95% CI low | D22: 95% CI high | E22: Significant
A23: Cascade − RAD-DINO, macro AUROC | B23: 0.0032 | C23: -0.0004 | D23: 0.0078 | E23: No
A24: Cascade − RAD-DINO, macro F1 | B24: 0.0217 | C24: 0.0061 | D24: 0.0364 | E24: Yes
A25: Average − RAD-DINO, macro AUROC | B25: 0.0076 | C25: 0.0047 | D25: 0.0116 | E25: Yes
A26: Average − RAD-DINO, macro F1 | B26: 0.0096 | C26: 0.0007 | D26: 0.0209 | E26: Yes
A28: Routing Sweep (per-image routing, Stage 2 = average)
A29: Threshold | B29: → Stage 2 | C29: ms/image | D29: Compute vs RAD-DINO | E29: Macro AUROC | F29: Macro F1 | G29: Recall | H29: Labels missed by CNN
A30: t = 0.70 | B30: 35.8% | C30: 14.3 | D30: 0.52 | E30: 0.8625 | F30: 0.3481 | G30: 0.375 | H30: 4380
A31: t = 0.80 (selected) | B31: 53.4% | C31: 19.1 | D31: 0.7 | E31: 0.8654 | F31: 0.3721 | G31: 0.4316 | H31: 2318
A32: t = 0.90 | B32: 80.1% | C32: 26.4 | D32: 0.97 | E32: 0.8682 | F32: 0.3601 | G32: 0.425 | H32: 565
A33: t = 0.95 | B33: 93.5% | C33: 30.1 | D33: 1.1 | E33: 0.869 | F33: 0.36 | G33: 0.432 | H33: 123
A34: t = 0.98 | B34: 99.4% | C34: 31.7 | D34: 1.16 | E34: 0.8698 | F34: 0.36 | G34: 0.4321 | H34: 7
A35: "Labels missed by CNN" = positive ground-truth labels in images the CNN decided alone (called negative) — findings the transformer never saw. This is the safety cost of routing and should be read alongside the compute saving.
A37: Per-Class Results — Earlier Analysis Run Only (t=0.90, Stage 2 = RAD-DINO alone; NOT the final selected configuration)
A38: Shown to illustrate per-disease behaviour and the cascade-vs-transformer pattern. Regenerate from cascade_per_class.csv for the final configuration (t=0.80, Stage 2 = average) before citing per-class numbers.
A39: Finding | B39: Support | C39: AUROC (cascade) | D39: AUROC (ViT) | E39: AUPRC (cascade) | F39: AUPRC (ViT) | G39: Precision | H39: Recall | I39: F1 (cascade) | J39: F1 (ViT)
A40: Atelectasis | B40: 1691 | C40: 0.842 | D40: 0.844 | E40: 0.41 | F40: 0.409 | G40: 0.343 | H40: 0.611 | I40: 0.44 | J40: 0.438
A41: Cardiomegaly | B41: 426 | C41: 0.918 | D41: 0.915 | E41: 0.306 | F41: 0.304 | G41: 0.347 | H41: 0.462 | I41: 0.397 | J41: 0.377
A42: Effusion | B42: 1935 | C42: 0.894 | D42: 0.894 | E42: 0.549 | F42: 0.549 | G42: 0.508 | H42: 0.614 | I42: 0.556 | J42: 0.556
A43: Infiltration | B43: 2941 | C43: 0.713 | D43: 0.709 | E43: 0.341 | F43: 0.339 | G43: 0.333 | H43: 0.518 | I43: 0.405 | J43: 0.401
A44: Mass | B44: 835 | C44: 0.894 | D44: 0.897 | E44: 0.414 | F44: 0.417 | G44: 0.43 | H44: 0.502 | I44: 0.463 | J44: 0.462
A45: Nodule | B45: 930 | C45: 0.827 | D45: 0.83 | E45: 0.288 | F45: 0.288 | G45: 0.368 | H45: 0.369 | I45: 0.368 | J45: 0.367
...

Sheet 7. Distillation
A1: 7. Distillation: CNN (ConvNeXt-Tiny) taught by the CNN + RAD-DINO average — official split, seed 42
A2: RAD-DINO is used only while training: its knowledge is copied into a new ConvNeXt-Tiny, which then runs alone at test time (CNN cost). Rules fixed before the run in evaluation_protocol.yaml v2.2.0. Source: results_distill (T10, T11, distill_go_no_go.json, train_log.csv, qc_session_D.json); reference systems link to sheets 4 and 5.
A4: A. How it works
A5: Component | B5: Details
A6: Why | B6: The cascade (sheet 5) failed because the CNN's misses are silent: a finding it cannot see gets a low score, so no gate can tell it apart from a true negative. Instead of routing at test time, RAD-DINO's knowledge is moved into the CNN during training.
A7: Teacher | B7: Mean of the calibrated probabilities of the trained CNN (M08) and RAD-DINO (M09) = the 'Average of both' system of sheet 4. Run once over the 73,916 training images (no augmentation).
A8: Student (M10) | B8: ConvNeXt-Tiny, 384 px, trained from ImageNet weights with exactly the M08 recipe (sheet 2). Only the training target changes.
A9: Training target | B9: 0.5 × real label + 0.5 × teacher probability, with the same ASL loss. Early stopping on validation macro AUROC against the real labels.
A10: Go / no-go rule | B10: Train the student only if the teacher's macro AUROC on the training images is below 0.95; above that, its soft labels would just copy the real labels (section B).
A11: Outcome rules | B11: Helps = significantly better than the CNN. Matches = lower 95% CI bound of (Distilled − RAD-DINO) macro AUROC above −0.005. Beats = significantly better than RAD-DINO. Primary metric: test macro AUROC (section F).
A12: Test-time cost | B12: Same network as the CNN: 4.0 ms per image at batch 32 = 0.18× RAD-DINO. RAD-DINO is not run at test time.
A13: Seed / TTA / checks | B13: One training seed (42); no test-time augmentation. Blocking checks QC-D1 to QC-D4 all passed: checkpoint hashes; both rebuilt teachers reproduce their saved validation logits exactly (correlation 1.00000); soft labels on training images only; identical test images.
A15: B. Go / no-go: is the teacher still informative on its own training images?
A16: Model | B16: Macro AUROC, train | C16: Macro AUROC, validation | D16: Train − validation
A17: CNN (M08) | B17: 0.90175466 | C17: 0.85977526 | D17: =B17-C17 -> 0.041979403
A18: RAD-DINO (M09) | B18: 0.91241137 | C18: 0.86511315 | D18: =B18-C18 -> 0.04729822
A19: Teacher = average of both | B19: 0.91645849 | C19: 0.87350997 | D19: =B19-C19 -> 0.042948523
A20: Go threshold (train AUROC must be below) | B20: 0.95
A21: Decision | B21: =IF(B19<B20,"GO","STOP") -> GO
A22: The teacher gives true positives an average probability of 0.28 and negatives 0.03 on training images: its soft labels are far from 0/1, so they carry information beyond the real labels. Blue = rule value from the protocol.
A24: C. Training: validation curve of the CNN (M08) and the distilled CNN (M10)
A25: Epoch | B25: Phase | C25: Val macro AUROC, CNN | D25: Val macro AUROC, distilled | E25: Difference | F25: Val loss, CNN | G25: Val loss, distilled
A26: 1 | B26: warmup | C26: 0.73930148 | D26: 0.75105146 | E26: =D26-C26 -> 0.011749985 | F26: 0.35478529 | G26: 0.35126314
A27: 2 | B27: finetune | C27: 0.81866047 | D27: 0.84259045 | E27: =D27-C27 -> 0.023929974 | F27: 0.32734227 | G27: 0.31299588
A28: 3 | B28: finetune | C28: 0.84053312 | D28: 0.85696398 | E28: =D28-C28 -> 0.016430851 | F28: 0.31303209 | G28: 0.30349556
A29: 4 | B29: finetune | C29: 0.85204382 | D29: 0.86222479 | E29: =D29-C29 -> 0.010180975 | F29: 0.30848756 | G29: 0.30197185
A30: 5 | B30: finetune | C30: 0.85602372 | D30: 0.86291884 | E30: =D30-C30 -> 0.0068951213 | F30: 0.3085281 | G30: 0.30092829
A31: 6 | B31: finetune | C31: 0.85977526 | D31: 0.86398712 | E31: =D31-C31 -> 0.0042118612 | F31: 0.30540708 | G31: 0.30022267
A32: 7 | B32: finetune | C32: 0.85822482 | D32: 0.86366201 | E32: =D32-C32 -> 0.005437194 | F32: 0.31262472 | G32: 0.30017722
A33: 8 | B33: finetune | C33: 0.85750293 | D33: 0.86314752 | E33: =D33-C33 -> 0.0056445944 | F33: 0.31603903 | G33: 0.30061007
A34: Best | C34: =MAX(C26:C33) -> 0.85977526 | D34: =MAX(D26:D33) -> 0.86398712 | E34: =D34-C34 -> 0.0042118612
A35: Best epoch | C35: =INDEX(A26:A33,MATCH(C34,C26:C33,0)) -> 6 | D35: =INDEX(A26:A33,MATCH(D34,D26:D33,0)) -> 6
A36: The CNN's validation loss rises after its best epoch (0.305 → 0.316); the distilled CNN's stays flat (0.300 → 0.301), a sign that soft labels reduce over-fitting to the noisy labels. Training took 2.56 h on a Tesla T4 (teacher soft-label pass: 50 min). Validation picked the epoch, so validation numbers are slightly optimistic; section D is the real test.
A38: D. Main results (test set, 25,596 images)
A39: System | B39: Macro AUROC | C39: 95% CI | D39: Macro AUPRC | E39: 95% CI | F39: Macro F1 | G39: 95% CI | H39: Micro F1 | I39: 95% CI | J39: Macro precision | K39: Macro recall | L39: Macro specificity | M39: Compute vs RAD-DINO (batch 32)
A40: CNN alone (ConvNeXt-Tiny) | B40: ='4. Official Split Results'!B6 -> 0.82630389 | C40: ='4. Official Split Results'!C6 -> 0.820–0.832 | D40: ='4. Official Split Results'!D6 -> 0.29884675 | E40: ='4. Official Split Results'!E6 -> 0.285–0.315 | F40: ='4. Official Split Results'!F6 -> 0.35391016 | G40: ='4. Official Split Results'!G6 -> 0.334–0.369 | H40: ='4. Official Split Results'!H6 -> 0.41717 | I40: ='4. Official Split Results'!I6 -> 0.409–0.425 | ... L40: ='4. Official Split Results'!L6 -> 0.90396065 | M40: ='5. Two-Stage Cascade'!D48 -> 0.17547568
A41: RAD-DINO alone | B41: ='4. Official Split Results'!B7 -> 0.83638611 | C41: ='4. Official Split Results'!C7 -> 0.830–0.842 | D41: ='4. Official Split Results'!D7 -> 0.32232227 | E41: ='4. Official Split Results'!E7 -> 0.310–0.337 | F41: ='4. Official Split Results'!F7 -> 0.37877978 | G41: ='4. Official Split Results'!G7 -> 0.365–0.390 | H41: ='4. Official Split Results'!H7 -> 0.43170705 | I41: ='4. Official Split Results'!I7 -> 0.424–0.439 | ... L41: ='4. Official Split Results'!L7 -> 0.90217277 | M41: ='5. Two-Stage Cascade'!D49 -> 1
A42: Average of both (every image) | B42: ='4. Official Split Results'!B8 -> 0.84277771 | C42: ='4. Official Split Results'!C8 -> 0.837–0.848 | D42: ='4. Official Split Results'!D8 -> 0.32918472 | E42: ='4. Official Split Results'!E8 -> 0.316–0.343 | F42: ='4. Official Split Results'!F8 -> 0.38178977 | G42: ='4. Official Split Results'!G8 -> 0.367–0.393 | H42: ='4. Official Split Results'!H8 -> 0.44211246 | I42: ='4. Official Split Results'!I8 -> 0.434–0.449 | ... L42: ='4. Official Split Results'!L8 -> 0.90919431 | M42: ='5. Two-Stage Cascade'!D50 -> 1.1754757
A43: Cascade t = 0.80 (sheet 5) | B43: ='4. Official Split Results'!B9 -> 0.83247514 | C43: ='4. Official Split Results'!C9 -> 0.826–0.838 | D43: ='4. Official Split Results'!D9 -> 0.31761424 | E43: ='4. Official Split Results'!E9 -> 0.305–0.332 | F43: ='4. Official Split Results'!F9 -> 0.37088237 | G43: ='4. Official Split Results'!G9 -> 0.356–0.382 | H43: ='4. Official Split Results'!H9 -> 0.42734521 | I43: ='4. Official Split Results'!I9 -> 0.419–0.435 | ... L43: ='4. Official Split Results'!L9 -> 0.90361631 | M43: ='5. Two-Stage Cascade'!D52 -> 0.95114376
A44: Distilled CNN (M10) | B44: 0.83386043 | C44: 0.828–0.839 | D44: 0.31461311 | E44: 0.301–0.330 | F44: 0.37018523 | G44: 0.352–0.384 | H44: 0.41915551 | I44: 0.411–0.427 | J44: 0.33258314 | K44: 0.46218095 | L44: 0.89926286 | M44: ='5. Two-Stage Cascade'!D48 -> 0.17547568
...
